Workbook

Sheet LEEME
A1: SISTEMA MENA v2.0 — DISCIPLINA, CUERPO, ESTUDIO Y VIDA ESPIRITUAL
B2: Versión | C2: v2.0 — 3 de septiembre de 2026 (PR reales, restricciones articulares, protocolo de suplementos)
B3: Construido a partir de | C3: Tu calendario real de Google (Sep 2026), el InBody del 12/05/2025 y el plan del Nut. Diego A. Espaillat Alejo.
B6: CÓMO USAR ESTE LIBRO
B7: HORARIO | C7: Tu semana bloque por bloque, ya cuadrada contra tu calendario real (Body Shop, FINTEL, Centro Español, PUCMM, Church SMP).
B8: LITURGICO | C8: Tus compromisos espirituales fijos y rotativos, y qué hacer cuando chocan con entrenamiento.
B9: NUTRICION | C9: Panel de cálculo: peso, TMB, TDEE, déficit y metas de macros. Las celdas AZULES son las únicas que editas.
B10: ALIMENTOS | C10: Tabla de referencia por 100 g de tus alimentos habituales + el peso en gramos de cada medida casera.
B11: MENUS | C11: Tres días modelo (Entreno / Ligero / Ayuno) con gramos exactos. Los totales se calculan solos desde ALIMENTOS.
B12: GYM | C12: Tu split de 4 días con series, repeticiones, RPE y descansos. Columna de carga vacía para que la llenes.
B13: BITACORA | C13: Registro diario. Solo llenas las celdas azules. El puntaje se calcula solo.
B14: DASHBOARD | C14: Estado de resultados de tu disciplina: qué renglón te está generando 'utilidad' y cuál te la está destruyendo.
B15: PESO | C15: Peso, cintura y % de grasa con media móvil de 4 registros para leer la tendencia, no el ruido.
B17: LAS 6 DECISIONES QUE TOMÉ POR TI (y por qué)
B18: 1. El ayuno va el VIERNES | C18: Es el día penitencial católico por excelencia, coincide con tus primeros viernes en el Sagrado Corazón, y — clave — lo convertí en día SIN pesas. Ayunar 24h y meter piernas el mismo día es cómo se pierde fuerza en un corte.
B19: 2. Piernas se mueve al JUEVES | C19: Tu calendario tiene gym Lu/Ma/Ju/Vi. Moví el bloque del viernes al MIÉRCOLES y dejé piernas el jueves. Así el viernes (ayuno) es descanso real y el sábado llegas fresco al baloncesto de PUCMM.
B20: 3. Tu horario no cerraba | C20: Pediste levantarte 5:00, gym 5:00-6:40, MÁS 50 pechadas, 25-50 dominadas y correr 30-40 min por la mañana. Eso no cabe en 100 minutos. Las pechadas y dominadas quedan como calentamiento/finisher dentro del gym; el correr queda en el bloque de cardio post-fuerza y el sábado.
B21: 4. Sueño: 5:00 + 11:00 PM = 6h | C21: Dijiste que prefieres 7h. No es posible con esos dos anclajes. Adelanté tu bloque CFI-FMVA a 19:45-21:45 y puse luces fuera 22:30 → 6.5h entre semana y 7-7.5h Vi/Sá/Do. Si quieres 7h fijas, hay que mover el despertar a 5:15.
B22: 5. Baloncesto los lunes: 3 de 4 | C22: Todos los lunes te cuesta 1h de estudio semanal y te deja durmiendo ~6h. Recomendación: 3 lunes al mes, y el 4º lunes libre lo usas para recuperar estudio. Está marcado así en HORARIO.
B23: 6. Proteína por encima de lo que pediste | C23: Pediste 150-200 g. En déficit y con este volumen, la meta calculada sale ~190 g. En días de entreno los menús llegan a ~215 g, que es exactamente lo que protege el músculo cuando se corta.
B25: LO QUE CAMBIÓ EN LA v2.0
B26: Alcohol: eliminado | C26: Fuera del libro. No se vuelve a mencionar.
B27: CoQ10 500 mg: agregado | C27: Está en el bloque de suplementos de NUTRICION y en el check diario de la BITACORA.
B28: Se eliminó TODA la sentadilla y TODA la pliometría | C28: Herniaciones discales + meniscos deteriorados. El bloque de saltos que tenía la v1.0 (saltos al cajón, salto amplio, skaters) era exactamente lo contrario de lo que tu rodilla necesita. Reemplazado por prensa, empuje de cadera y trabajo de máquina — donde tú ya mueves 800 lb sin problema.
B29: Se eliminó toda flexión lumbar cargada | C29: Fuera: rueda abdominal, crunch en polea, leñador en polea, remo con barra inclinado. Entraron: press Pallof, dead bug, bird dog, paseo maleta y remo con pecho apoyado. Mismo estímulo, sin cargar el disco en flexión.
B30: Progresión con tus números reales | C30: Nueva hoja PROGRESION con 12 semanas de cargas concretas calculadas desde tus PR, no rangos genéricos.
B32: DOS CONVERSACIONES MÉDICAS QUE NO PUEDO TENER YO
B33: La rosuvastatina — esto es lo más importante de este archivo | C33: Vas a dejar un medicamento que tomas desde los 18 años. Un estatina a esa edad casi nunca es rutina: normalmente responde a hipercolesterolemia familiar o a una dislipidemia significativa. Y hay algo que necesitas saber con precisión: el CoQ10 NO baja el LDL. El CoQ10 sirve para los síntomas musculares que causan las estatinas, no sustituye su efecto sobre el colesterol. Si dejas la rosuvastatina y tomas CoQ10, tu LDL queda sin tratamiento.
B34: Cómo convertir eso en un experimento y no en una apuesta | C34: Tú eres analista: no cerrarías una posición sin medir. Haz esto — (1) Perfil lipídico + ALT/AST ESTA SEMANA, antes de cambiar nada. Ese es tu dato base. (2) Dile al médico que lo prescribió que lo vas a intentar por dieta y ejercicio, para que él decida el intervalo de control. Dejarlo en silencio te quita la única red de seguridad que tienes. (3) Repite el panel a las 12 semanas. Si el LDL baja a rango, tienes evidencia para defender tu decisión ante él. Si no baja, lo sabes a tiempo. Agregué las filas de seguimiento en la hoja PESO.
B35: El ayuno de 24 horas | C35: Práctica legítima y antigua. Aun así, con las notas hepáticas y de ansiedad de tu plan nutricional, coméntaselo a tu nutriólogo antes de la primera semana. Regla no negociable: agua y electrolitos todo el día; si aparece mareo, temblor, visión borrosa o taquicardia, se rompe y ya.
B36: Peso muerto con hernias discales | C36: Sigues en 315x3, así que asumo que ya es parte de tu práctica. Aun así lo bajé a peso muerto rumano con barra hexagonal o mancuernas y lo marqué como CONDICIONAL en la hoja GYM. El empuje de cadera quedó como movimiento principal de cadena posterior porque carga el glúteo sin comprimir la columna. Si tu médico te autoriza el convencional, súbelo de nuevo.
B38: LA REGLA DE ORO
B39: Adherencia > perfección | C39: Un 80% sostenido 12 semanas te lleva mucho más lejos que un 100% sostenido 9 días. El DASHBOARD está diseñado para que veas el promedio, no el día suelto.

Sheet HORARIO
A1: HORARIO SEMANAL — cuadrado contra tu calendario real
A2: Despertar 5:00 · Luces fuera 22:30 (Lu-Ju) / 23:00 (Vi-Do) · Trabajo FINTEL 8:30-12:30 y 14:00-17:15 · Gym Body Shop
A4: LUNES | B4: DÍA 1 — Pecho / Tríceps / Antebrazo / Abs
A5: Hora | B5: Actividad | C5: Detalle | D5: Bloque
A6: 05:00 | B6: Despertar | C6: 500 ml agua + 5 g creatina + electrolito sin calorías | D6: Bloque 1: arranque
A7: 05:05 | B7: Cama + bulto | C7: Cama tendida. El bulto se prepara la NOCHE anterior; aquí solo lo verificas.
A8: 05:10 | B8: Briefing de mercado | C8: 10 min: cierre asiático, futuros US, DXY, WTI, oro, noticias BCRD. Lo lees, no lo estudias.
A9: 05:25 | B9: Salida a Body Shop
A10: 05:35 | B10: GYM — Día 1 | C10: 55 min fuerza + 15 min cardio Z2 (ver hoja GYM) | D10: Bloque 2: cuerpo
A11: 06:50 | B11: Regreso a casa
A12: 07:00 | B12: Baño + desayuno | C12: Desayuno post-entreno del menú (día ENTRENO)
A13: 07:45 | B13: Salida al trabajo
A14: 08:00 | B14: Pre-Market Analysis | C14: Ya en tu calendario | D14: Bloque 3: trabajo
A15: 08:30 | B15: Trabajo — Bloque 1 | C15: FINTEL
A16: 12:30 | B16: Almuerzo | C16: Comida principal del día. Pesar antes de servir.
A17: 14:00 | B17: Trabajo — Bloque 2 | C17: FINTEL
A18: 16:55 | B18: ROSARIO | C18: 20 min antes de salir. Es un bloque, no un hueco. | D18: Bloque 4: alma
A19: 17:20 | B19: Merienda | C19: Whey + pan integral + fruta
A20: 19:00 | B20: BALONCESTO | C20: 3 lunes al mes. El 4º lunes: estudio 19:45-21:45 y a dormir temprano. | D20: Bloque 5: PM
A21: 21:15 | B21: Cena | C21: Menú día ENTRENO
A22: 21:45 | B22: Estudio CFI-FMVA | C22: 1h (día corto por baloncesto). Se compensa el domingo.
A23: 22:45 | B23: Lectura 15 min + oración de la noche
A24: 23:00 | B24: Dormir | C24: ≈6h. Es el día más corto de la semana, por diseño.
A26: MARTES | B26: DÍA 2 — Espalda / Bíceps / Deltoide posterior / Abs
A27: Hora | B27: Actividad | C27: Detalle | D27: Bloque
A28: 05:00 | B28: Despertar | C28: Agua + creatina + electrolito | D28: Bloque 1
A29: 05:05 | B29: Cama + bulto
A30: 05:10 | B30: Briefing de mercado | C30: 10 min
A31: 05:35 | B31: GYM — Día 2 | C31: 55 min fuerza + 15 min cardio | D31: Bloque 2
A32: 07:00 | B32: Baño + desayuno
A33: 08:00 | B33: Pre-Market Analysis | D33: Bloque 3
A34: 08:30 | B34: Trabajo — Bloque 1 | C34: FINTEL
A35: 12:30 | B35: Almuerzo
A36: 14:00 | B36: Trabajo — Bloque 2 | C36: FINTEL
A37: 16:55 | B37: ROSARIO | C37: 20 min | D37: Bloque 4
A38: 18:30 | B38: MISA — Church SMP | C38: Ya en tu calendario. Martes es misa fija.
A39: 19:35 | B39: Cena | C39: Menú día ENTRENO | D39: Bloque 5
A40: 19:50 | B40: Estudio CFI-FMVA / SIMV | C40: 2h
A41: 21:50 | B41: Lectura 20 min
A42: 22:15 | B42: Baño + preparar bulto + oración de la noche
...

Sheet LITURGICO
A1: CALENDARIO LITÚRGICO Y ESPIRITUAL
A3: Frecuencia | B3: Día / Hora | C3: Lugar | D3: Nota operativa
A4: Diario | B4: 16:55 (antes de salir) | C4: Trabajo / camino | D4: Rosario. Los viernes puedes rezarlo durante la caminata de la mañana.
A5: Diario | B5: 22:15-23:00 | C5: Casa | D5: Oración de la noche antes de acostarte. Examen del día: qué se cumplió y qué no.
A6: Lunes, Jueves, Viernes | B6: 18:30-19:30 | C6: Church SMP | D6: Misa. Ya en tu calendario. Los lunes de baloncesto, se sustituye por misa dominical reforzada.
A7: Cada MARTES | B7: 18:30 | C7: Church SMP | D7: Misa fija de martes. Innegociable — es el ancla de tu semana.
A8: Cada SÁBADO | B8: 19:00 | C8: Parroquia | D8: Misa vespertina. Cumple el precepto dominical.
A9: Cada DOMINGO | B9: 10:30 AM o 12:00 M | C9: Parroquia | D9: Si fuiste el sábado, el domingo queda libre para meal prep y estudio.
A10: 1er VIERNES del mes | B10: Tarde/noche | C10: Sagrado Corazón — Noviciado jesuita | D10: Coincide con tu día de ayuno. Es la combinación ideal: penitencia + devoción.
A11: 2º JUEVES del mes | B11: Por confirmar | C11: Centro Bellarmino | D11: Adora y Confía. Sustituye la misa de Church SMP ese jueves.
A12: 2º SÁBADO del mes | B12: 19:00 | C12: San Ramón | D12: Misa.
A13: 3er SÁBADO del mes | B13: 19:00 | C13: San Ramón | D13: Misa de Jóvenes en Cristo.
A14: 3er DOMINGO del mes | B14: 10:00 AM | C14: San Martín | D14: Misa. Ese domingo el meal prep se corre a las 15:00.
A15: Cada VIERNES | B15: Todo el día | C15: — | D15: AYUNO. Cena del jueves 19:35 → cena del viernes 19:45. Agua, electrolitos, café negro y té sin azúcar.
A17: REGLA DE CONFLICTO
A18: Si un compromiso espiritual choca con entrenamiento: gana el compromiso espiritual. El gym se mueve; la misa no.
A19: Si choca con estudio: gana el compromiso espiritual, y el estudio se recupera el domingo (el bloque del domingo tiene holgura para eso).
A20: Si choca con baloncesto: gana el compromiso espiritual. Por eso el baloncesto del lunes es 3 de 4 semanas y no 4 de 4.

Sheet NUTRICION
A1: PANEL DE CÁLCULO NUTRICIONAL
B2: AZUL = tú lo editas. NEGRO = fórmula, no lo toques.
B4: DATOS PERSONALES
B5: Peso actual (lb) | C5: 220 | E5: Dato que me diste el 02/09/2026.
B6: Peso actual (kg) | C6: =C5/2.2046 -> 99.791345
B7: Estatura (cm) | C7: 180 | E7: InBody 12/05/2025.
B8: Edad (años) | C8: 22
B9: % grasa corporal estimado | C9: 0.21 | E9: Tu estimación. El InBody de 05/2025 dio 22.8% a 97.7 kg. Confírmalo con una nueva medición.
B10: Masa magra (kg) | C10: =C6*(1-C9) -> 78.835163 | E10: Lo que estamos protegiendo durante el corte.
B12: GASTO ENERGÉTICO
B13: TMB — Mifflin-St Jeor (kcal) | C13: =10*C6+6.25*C7-5*C8+5 -> 2017.9135 | E13: El InBody reportó TMB 1,999 kcal en 05/2025. Coherente.
B14: Factor de actividad | C14: 1.55 | E14: 1.55 = 4 días de pesas + cardio diario + deportes. Si bajas >1 kg/semana dos semanas seguidas, súbelo a 1.65.
B15: TDEE — gasto total (kcal) | C15: =C13*C14 -> 3127.7659 | E15: Tu punto de equilibrio: comiendo esto, no subes ni bajas.
B16: Déficit día ENTRENO (kcal) | C16: 400
B17: Déficit día LIGERO (kcal) | C17: 700
B19: METAS DIARIAS
B20: Calorías — día ENTRENO (Lu/Ma/Mi/Ju) | C20: =ROUND((C15-C16)/50,0)*50 -> 2750
B21: Calorías — día LIGERO (Sá/Do) | C21: =ROUND((C15-C17)/50,0)*50 -> 2450
B22: Calorías — día AYUNO (Vi) | C22: 0
B23: Proteína (g/día) | C23: =ROUND(C10*2.4,0) -> 189
B24: Grasa (g/día) | C24: =ROUND(C6*0.7,0) -> 70
B25: Carbohidratos — día ENTRENO (g) | C25: =ROUND((C20-C23*4-C24*9)/4,0) -> 341
B26: Carbohidratos — día LIGERO (g) | C26: =ROUND((C21-C23*4-C24*9)/4,0) -> 266
B27: Agua (litros/día) | C27: 5
B28: Creatina monohidratada (g/día) | C28: 5
B29: Sueño mínimo (horas) | C29: 6.5
B30: Estudio mínimo (minutos/día) | C30: 120
B32: LECTURA DEL DÉFICIT
B33: Ingesta semanal total (kcal) | C33: =C20*4+C21*2+C22 -> 15900
B34: Promedio diario real (kcal) | C34: =C33/7 -> 2271.4286
B35: Déficit promedio diario (kcal) | C35: =C15-C34 -> 856.33728
B36: Pérdida semanal proyectada (kg) | C36: =C35*7/7700 -> 0.77848844
B37: Pérdida semanal proyectada (lb) | C37: =C36*2.2046 -> 1.7162556
B38: Si la pérdida real supera 1 kg/semana dos semanas seguidas, sube el factor de actividad o reduce el déficit. Bajar demasiado rápido cuesta músculo y fuerza — que es exactamente lo que no quieres.
B40: PROTOCOLO DE SUPLEMENTOS
B41: Creatina monohidratada | C41: 5 g | E41: Con el agua de la mañana. Se salta el viernes por comodidad, no cambia nada: la creatina se satura en el músculo.
B42: CoQ10 500 mg | C42: 1 cápsula | E42: Con una comida que tenga grasa (desayuno o cena) — es liposoluble, en ayunas se absorbe mal. IMPORTANTE: el CoQ10 no baja el LDL. Ver la nota de la hoja LEEME.
B43: Proteína whey | C43: 1-2 scoops | E43: Solo para cerrar la brecha de proteína, no como comida. La comida real primero.
B44: Multivitamínico | C44: 1 | E44: Ya en uso.
B45: Colágeno | C45: según etiqueta | E45: Ya en uso. Mejor 30-60 min antes de entrenar.
...

Sheet ALIMENTOS
A1: TABLA DE ALIMENTOS — valores por 100 g
A2: Regla: la carne y el pescado se pesan CRUDOS. El arroz, la pasta y la avena se pesan SECOS. Si ya está cocido, el peso cambia y el cálculo se rompe.
A3: Alimento | B3: Estado | C3: kcal/100g | D3: Prot/100g | E3: Carb/100g | F3: Grasa/100g | G3: Medida común | H3: g por medida | I3: Nota
A4: Pechuga de pollo | B4: crudo | C4: 120 | D4: 22.5 | E4: 0 | F4: 2.6 | G4: 1 pechuga mediana | H4: 180 | I4: Tu mejor fuente: 22.5 g de proteína por 100 g y casi nada de grasa.
A5: Tilapia | B5: crudo | C5: 96 | D5: 20.1 | E5: 0 | F5: 1.7 | G5: 1 filete | H5: 150
A6: Salmón | B6: crudo | C6: 208 | D6: 20.4 | E6: 0 | F6: 13.4 | G6: 1 filete | H6: 150 | I6: Omega-3. Recomendado en tu plan del nutriólogo.
A7: Lubina / Dorada | B7: crudo | C7: 97 | D7: 18.4 | E7: 0 | F7: 2 | G7: 1 filete | H7: 150
A8: Carne molida de res 90/10 | B8: crudo | C8: 176 | D8: 20 | E8: 0 | F8: 10 | G8: 1 porción | H8: 150 | I8: Pide la molida magra. La 80/20 tiene el doble de grasa.
A9: Carne molida de res 80/20 | B9: crudo | C9: 254 | D9: 17 | E9: 0 | F9: 20 | G9: 1 porción | H9: 150 | I9: Evítala en corte: menos proteína y más del doble de grasa.
A10: Res — falda / bistec magro | B10: crudo | C10: 145 | D10: 21.5 | E10: 0 | F10: 6 | G10: 1 bistec | H10: 150
A11: Lomo de cerdo | B11: crudo | C11: 143 | D11: 21 | E11: 0 | F11: 6 | G11: 1 porción | H11: 150
A12: Chuleta de cerdo magra | B12: crudo | C12: 172 | D12: 20.5 | E12: 0 | F12: 9.5 | G12: 1 chuleta | H12: 160
A13: Huevo entero | B13: crudo | C13: 143 | D13: 12.6 | E13: 0.7 | F13: 9.9 | G13: 1 huevo grande | H13: 50 | I13: 1 huevo = 72 kcal, 6.3 g proteína.
A14: Clara de huevo | B14: crudo | C14: 52 | D14: 10.9 | E14: 0.7 | F14: 0.2 | G14: 1 clara | H14: 33 | I14: El truco para subir proteína sin grasa: 4 claras = 44 g proteína... no, 14 g. Barato en kcal.
A15: Proteína whey | B15: polvo | C15: 400 | D15: 80 | E15: 10 | F15: 5 | G15: 1 scoop | H15: 30 | I15: 1 scoop = 24 g proteína. Verifica la etiqueta de TU marca.
A16: Leche sin lactosa | B16: líquido | C16: 50 | D16: 3.3 | E16: 5 | F16: 2 | G16: 1 taza | H16: 240
A17: Yogur griego natural bajo en grasa | B17: — | C17: 59 | D17: 10 | E17: 3.6 | F17: 0.4 | G17: 1 pote | H17: 150
A18: Queso feta | B18: — | C18: 264 | D18: 14.2 | E18: 4.1 | F18: 21.3 | G18: 1 porción | H18: 30
A19: Arroz blanco | B19: seco | C19: 360 | D19: 6.6 | E19: 79.3 | F19: 0.6 | G19: 1 taza seca | H19: 200 | I19: 1 taza seca rinde ~3 tazas cocidas.
A20: Arroz integral | B20: seco | C20: 360 | D20: 7.5 | E20: 76 | F20: 2.9 | G20: 1 taza seca | H20: 195
A21: Pasta integral | B21: seco | C21: 348 | D21: 13 | E21: 71 | F21: 2.5 | G21: 1 taza seca | H21: 105
A22: Avena en hojuelas | B22: seco | C22: 389 | D22: 16.9 | E22: 66.3 | F22: 6.9 | G22: 1/2 taza | H22: 45
A23: Pan integral | B23: — | C23: 250 | D23: 13 | E23: 43 | F23: 3.4 | G23: 1 rebanada | H23: 28
A24: Tortilla de maíz | B24: — | C24: 218 | D24: 5.7 | E24: 44.6 | F24: 2.9 | G24: 1 tortilla | H24: 30
A25: Batata | B25: crudo | C25: 86 | D25: 1.6 | E25: 20.1 | F25: 0.1 | G25: 1 mediana | H25: 130
A26: Papa | B26: crudo | C26: 77 | D26: 2 | E26: 17.5 | F26: 0.1 | G26: 1 mediana | H26: 170
A27: Lentejas | B27: cocidas | C27: 116 | D27: 9 | E27: 20.1 | F27: 0.4 | G27: 1 taza cocida | H27: 200 | I27: Aquí sí se pesa cocida.
A28: Aguacate | B28: — | C28: 160 | D28: 2 | E28: 8.5 | F28: 14.7 | G28: 1/2 unidad | H28: 75 | I28: Grasa saludable, pero densa. Pésalo siempre.
A29: Aceite de oliva | B29: — | C29: 884 | D29: 0 | E29: 0 | F29: 100 | G29: 1 cucharada | H29: 14 | I29: Una cucharada mal medida = 120 kcal invisibles. Es el error #1 en un corte.
A30: Mantequilla de maní | B30: — | C30: 588 | D30: 25 | E30: 20 | F30: 50 | G30: 1 cucharada | H30: 16
A31: Almendras | B31: — | C31: 579 | D31: 21.2 | E31: 21.6 | F31: 49.9 | G31: 1 puñado | H31: 28
A32: Pistachos | B32: — | C32: 562 | D32: 20.2 | E32: 27.2 | F32: 45.3 | G32: 1 puñado | H32: 28
A33: Maní natural | B33: — | C33: 567 | D33: 25.8 | E33: 16.1 | F33: 49.2 | G33: 1 puñado | H33: 28
A34: Semillas de cajuil (anacardo) | B34: — | C34: 553 | D34: 18.2 | E34: 30.2 | F34: 43.9 | G34: 1 cucharada | H34: 15
A35: Hummus | B35: — | C35: 166 | D35: 7.9 | E35: 14.3 | F35: 9.6 | G35: 1 cucharada | H35: 15
A36: Banana (guineo) | B36: — | C36: 89 | D36: 1.1 | E36: 22.8 | F36: 0.3 | G36: 1 mediana | H36: 118
A37: Mandarina | B37: — | C37: 53 | D37: 0.8 | E37: 13.3 | F37: 0.3 | G37: 1 unidad | H37: 90
A38: Kiwi | B38: — | C38: 61 | D38: 1.1 | E38: 14.7 | F38: 0.5 | G38: 1 unidad | H38: 75
A39: Mango | B39: — | C39: 60 | D39: 0.8 | E39: 15 | F39: 0.4 | G39: 1/2 unidad | H39: 100
A40: Papaya / Lechosa | B40: — | C40: 43 | D40: 0.5 | E40: 10.8 | F40: 0.3 | G40: 1 taza en cubos | H40: 145
...

Sheet MENUS
A1: MENÚS MODELO — gramos exactos, totales automáticos
A2: Los macros se calculan solos desde la hoja ALIMENTOS. Cambia solo la columna GRAMOS (azul) o el nombre del alimento (debe escribirse EXACTO igual que en ALIMENTOS).
A4: DÍA ENTRENO — Lunes, Martes, Miércoles, Jueves
A5: Comida | B5: Alimento | C5: Gramos | D5: kcal | E5: Proteína | F5: Carbs | G5: Grasa | H5: Nota
A6: Desayuno | B6: Huevo entero | C6: 150 | D6: =IFERROR(INDEX(ALIMENTOS!$C$4:$C$47,MATCH($B6,ALIMENTOS!$A$4:$A$47,0))*$C6/100,"") -> 214.5 | E6: =IFERROR(INDEX(ALIMENTOS!$D$4:$D$47,MATCH($B6,ALIMENTOS!$A$4:$A$47,0))*$C6/100,"") -> 18.9 | F6: =IFERROR(INDEX(ALIMENTOS!$E$4:$E$47,MATCH($B6,ALIMENTOS!$A$4:$A$47,0))*$C6/100,"") -> 1.05 | G6: =IFERROR(INDEX(ALIMENTOS!$F$4:$F$47,MATCH($B6,ALIMENTOS!$A$4:$A$47,0))*$C6/100,"") -> 14.85 | H6: 3 huevos grandes
A7: Desayuno | B7: Clara de huevo | C7: 200 | D7: =IFERROR(INDEX(ALIMENTOS!$C$4:$C$47,MATCH($B7,ALIMENTOS!$A$4:$A$47,0))*$C7/100,"") -> 104 | E7: =IFERROR(INDEX(ALIMENTOS!$D$4:$D$47,MATCH($B7,ALIMENTOS!$A$4:$A$47,0))*$C7/100,"") -> 21.8 | F7: =IFERROR(INDEX(ALIMENTOS!$E$4:$E$47,MATCH($B7,ALIMENTOS!$A$4:$A$47,0))*$C7/100,"") -> 1.4 | G7: =IFERROR(INDEX(ALIMENTOS!$F$4:$F$47,MATCH($B7,ALIMENTOS!$A$4:$A$47,0))*$C7/100,"") -> 0.4 | H7: 6 claras. Aquí está el truco de la proteína barata.
A8: Desayuno | B8: Avena en hojuelas | C8: 90 | D8: =IFERROR(INDEX(ALIMENTOS!$C$4:$C$47,MATCH($B8,ALIMENTOS!$A$4:$A$47,0))*$C8/100,"") -> 350.1 | E8: =IFERROR(INDEX(ALIMENTOS!$D$4:$D$47,MATCH($B8,ALIMENTOS!$A$4:$A$47,0))*$C8/100,"") -> 15.21 | F8: =IFERROR(INDEX(ALIMENTOS!$E$4:$E$47,MATCH($B8,ALIMENTOS!$A$4:$A$47,0))*$C8/100,"") -> 59.67 | G8: =IFERROR(INDEX(ALIMENTOS!$F$4:$F$47,MATCH($B8,ALIMENTOS!$A$4:$A$47,0))*$C8/100,"") -> 6.21 | H8: Pesada SECA
A9: Desayuno | B9: Banana (guineo) | C9: 150 | D9: =IFERROR(INDEX(ALIMENTOS!$C$4:$C$47,MATCH($B9,ALIMENTOS!$A$4:$A$47,0))*$C9/100,"") -> 133.5 | E9: =IFERROR(INDEX(ALIMENTOS!$D$4:$D$47,MATCH($B9,ALIMENTOS!$A$4:$A$47,0))*$C9/100,"") -> 1.65 | F9: =IFERROR(INDEX(ALIMENTOS!$E$4:$E$47,MATCH($B9,ALIMENTOS!$A$4:$A$47,0))*$C9/100,"") -> 34.2 | G9: =IFERROR(INDEX(ALIMENTOS!$F$4:$F$47,MATCH($B9,ALIMENTOS!$A$4:$A$47,0))*$C9/100,"") -> 0.45
A10: Desayuno | B10: Mantequilla de maní | C10: 16 | D10: =IFERROR(INDEX(ALIMENTOS!$C$4:$C$47,MATCH($B10,ALIMENTOS!$A$4:$A$47,0))*$C10/100,"") -> 94.08 | E10: =IFERROR(INDEX(ALIMENTOS!$D$4:$D$47,MATCH($B10,ALIMENTOS!$A$4:$A$47,0))*$C10/100,"") -> 4 | F10: =IFERROR(INDEX(ALIMENTOS!$E$4:$E$47,MATCH($B10,ALIMENTOS!$A$4:$A$47,0))*$C10/100,"") -> 3.2 | G10: =IFERROR(INDEX(ALIMENTOS!$F$4:$F$47,MATCH($B10,ALIMENTOS!$A$4:$A$47,0))*$C10/100,"") -> 8 | H10: 1 cucharada rasa, no colmada
A11: Almuerzo | B11: Pechuga de pollo | C11: 250 | D11: =IFERROR(INDEX(ALIMENTOS!$C$4:$C$47,MATCH($B11,ALIMENTOS!$A$4:$A$47,0))*$C11/100,"") -> 300 | E11: =IFERROR(INDEX(ALIMENTOS!$D$4:$D$47,MATCH($B11,ALIMENTOS!$A$4:$A$47,0))*$C11/100,"") -> 56.25 | F11: =IFERROR(INDEX(ALIMENTOS!$E$4:$E$47,MATCH($B11,ALIMENTOS!$A$4:$A$47,0))*$C11/100,"") -> 0 | G11: =IFERROR(INDEX(ALIMENTOS!$F$4:$F$47,MATCH($B11,ALIMENTOS!$A$4:$A$47,0))*$C11/100,"") -> 6.5 | H11: Peso CRUDO
A12: Almuerzo | B12: Arroz blanco | C12: 130 | D12: =IFERROR(INDEX(ALIMENTOS!$C$4:$C$47,MATCH($B12,ALIMENTOS!$A$4:$A$47,0))*$C12/100,"") -> 468 | E12: =IFERROR(INDEX(ALIMENTOS!$D$4:$D$47,MATCH($B12,ALIMENTOS!$A$4:$A$47,0))*$C12/100,"") -> 8.58 | F12: =IFERROR(INDEX(ALIMENTOS!$E$4:$E$47,MATCH($B12,ALIMENTOS!$A$4:$A$47,0))*$C12/100,"") -> 103.09 | G12: =IFERROR(INDEX(ALIMENTOS!$F$4:$F$47,MATCH($B12,ALIMENTOS!$A$4:$A$47,0))*$C12/100,"") -> 0.78 | H12: Peso SECO
A13: Almuerzo | B13: Aguacate | C13: 60 | D13: =IFERROR(INDEX(ALIMENTOS!$C$4:$C$47,MATCH($B13,ALIMENTOS!$A$4:$A$47,0))*$C13/100,"") -> 96 | E13: =IFERROR(INDEX(ALIMENTOS!$D$4:$D$47,MATCH($B13,ALIMENTOS!$A$4:$A$47,0))*$C13/100,"") -> 1.2 | F13: =IFERROR(INDEX(ALIMENTOS!$E$4:$E$47,MATCH($B13,ALIMENTOS!$A$4:$A$47,0))*$C13/100,"") -> 5.1 | G13: =IFERROR(INDEX(ALIMENTOS!$F$4:$F$47,MATCH($B13,ALIMENTOS!$A$4:$A$47,0))*$C13/100,"") -> 8.82
A14: Almuerzo | B14: Ensalada verde mixta | C14: 150 | D14: =IFERROR(INDEX(ALIMENTOS!$C$4:$C$47,MATCH($B14,ALIMENTOS!$A$4:$A$47,0))*$C14/100,"") -> 25.5 | E14: =IFERROR(INDEX(ALIMENTOS!$D$4:$D$47,MATCH($B14,ALIMENTOS!$A$4:$A$47,0))*$C14/100,"") -> 1.8 | F14: =IFERROR(INDEX(ALIMENTOS!$E$4:$E$47,MATCH($B14,ALIMENTOS!$A$4:$A$47,0))*$C14/100,"") -> 4.5 | G14: =IFERROR(INDEX(ALIMENTOS!$F$4:$F$47,MATCH($B14,ALIMENTOS!$A$4:$A$47,0))*$C14/100,"") -> 0.3
A15: Almuerzo | B15: Aceite de oliva | C15: 7 | D15: =IFERROR(INDEX(ALIMENTOS!$C$4:$C$47,MATCH($B15,ALIMENTOS!$A$4:$A$47,0))*$C15/100,"") -> 61.88 | E15: =IFERROR(INDEX(ALIMENTOS!$D$4:$D$47,MATCH($B15,ALIMENTOS!$A$4:$A$47,0))*$C15/100,"") -> 0 | F15: =IFERROR(INDEX(ALIMENTOS!$E$4:$E$47,MATCH($B15,ALIMENTOS!$A$4:$A$47,0))*$C15/100,"") -> 0 | G15: =IFERROR(INDEX(ALIMENTOS!$F$4:$F$47,MATCH($B15,ALIMENTOS!$A$4:$A$47,0))*$C15/100,"") -> 7 | H15: 1/2 cucharada
A16: Merienda | B16: Proteína whey | C16: 30 | D16: =IFERROR(INDEX(ALIMENTOS!$C$4:$C$47,MATCH($B16,ALIMENTOS!$A$4:$A$47,0))*$C16/100,"") -> 120 | E16: =IFERROR(INDEX(ALIMENTOS!$D$4:$D$47,MATCH($B16,ALIMENTOS!$A$4:$A$47,0))*$C16/100,"") -> 24 | F16: =IFERROR(INDEX(ALIMENTOS!$E$4:$E$47,MATCH($B16,ALIMENTOS!$A$4:$A$47,0))*$C16/100,"") -> 3 | G16: =IFERROR(INDEX(ALIMENTOS!$F$4:$F$47,MATCH($B16,ALIMENTOS!$A$4:$A$47,0))*$C16/100,"") -> 1.5 | H16: 1 scoop
A17: Merienda | B17: Pan integral | C17: 56 | D17: =IFERROR(INDEX(ALIMENTOS!$C$4:$C$47,MATCH($B17,ALIMENTOS!$A$4:$A$47,0))*$C17/100,"") -> 140 | E17: =IFERROR(INDEX(ALIMENTOS!$D$4:$D$47,MATCH($B17,ALIMENTOS!$A$4:$A$47,0))*$C17/100,"") -> 7.28 | F17: =IFERROR(INDEX(ALIMENTOS!$E$4:$E$47,MATCH($B17,ALIMENTOS!$A$4:$A$47,0))*$C17/100,"") -> 24.08 | G17: =IFERROR(INDEX(ALIMENTOS!$F$4:$F$47,MATCH($B17,ALIMENTOS!$A$4:$A$47,0))*$C17/100,"") -> 1.904 | H17: 2 rebanadas
A18: Merienda | B18: Mandarina | C18: 100 | D18: =IFERROR(INDEX(ALIMENTOS!$C$4:$C$47,MATCH($B18,ALIMENTOS!$A$4:$A$47,0))*$C18/100,"") -> 53 | E18: =IFERROR(INDEX(ALIMENTOS!$D$4:$D$47,MATCH($B18,ALIMENTOS!$A$4:$A$47,0))*$C18/100,"") -> 0.8 | F18: =IFERROR(INDEX(ALIMENTOS!$E$4:$E$47,MATCH($B18,ALIMENTOS!$A$4:$A$47,0))*$C18/100,"") -> 13.3 | G18: =IFERROR(INDEX(ALIMENTOS!$F$4:$F$47,MATCH($B18,ALIMENTOS!$A$4:$A$47,0))*$C18/100,"") -> 0.3
A19: Cena | B19: Tilapia | C19: 250 | D19: =IFERROR(INDEX(ALIMENTOS!$C$4:$C$47,MATCH($B19,ALIMENTOS!$A$4:$A$47,0))*$C19/100,"") -> 240 | E19: =IFERROR(INDEX(ALIMENTOS!$D$4:$D$47,MATCH($B19,ALIMENTOS!$A$4:$A$47,0))*$C19/100,"") -> 50.25 | F19: =IFERROR(INDEX(ALIMENTOS!$E$4:$E$47,MATCH($B19,ALIMENTOS!$A$4:$A$47,0))*$C19/100,"") -> 0 | G19: =IFERROR(INDEX(ALIMENTOS!$F$4:$F$47,MATCH($B19,ALIMENTOS!$A$4:$A$47,0))*$C19/100,"") -> 4.25 | H19: Intercambiable con lubina, dorada o pollo
A20: Cena | B20: Batata | C20: 250 | D20: =IFERROR(INDEX(ALIMENTOS!$C$4:$C$47,MATCH($B20,ALIMENTOS!$A$4:$A$47,0))*$C20/100,"") -> 215 | E20: =IFERROR(INDEX(ALIMENTOS!$D$4:$D$47,MATCH($B20,ALIMENTOS!$A$4:$A$47,0))*$C20/100,"") -> 4 | F20: =IFERROR(INDEX(ALIMENTOS!$E$4:$E$47,MATCH($B20,ALIMENTOS!$A$4:$A$47,0))*$C20/100,"") -> 50.25 | G20: =IFERROR(INDEX(ALIMENTOS!$F$4:$F$47,MATCH($B20,ALIMENTOS!$A$4:$A$47,0))*$C20/100,"") -> 0.25 | H20: Peso CRUDO
A21: Cena | B21: Vegetales salteados mixtos | C21: 200 | D21: =IFERROR(INDEX(ALIMENTOS!$C$4:$C$47,MATCH($B21,ALIMENTOS!$A$4:$A$47,0))*$C21/100,"") -> 90 | E21: =IFERROR(INDEX(ALIMENTOS!$D$4:$D$47,MATCH($B21,ALIMENTOS!$A$4:$A$47,0))*$C21/100,"") -> 4 | F21: =IFERROR(INDEX(ALIMENTOS!$E$4:$E$47,MATCH($B21,ALIMENTOS!$A$4:$A$47,0))*$C21/100,"") -> 16 | G21: =IFERROR(INDEX(ALIMENTOS!$F$4:$F$47,MATCH($B21,ALIMENTOS!$A$4:$A$47,0))*$C21/100,"") -> 1
A22: Cena | B22: Aceite de oliva | C22: 7 | D22: =IFERROR(INDEX(ALIMENTOS!$C$4:$C$47,MATCH($B22,ALIMENTOS!$A$4:$A$47,0))*$C22/100,"") -> 61.88 | E22: =IFERROR(INDEX(ALIMENTOS!$D$4:$D$47,MATCH($B22,ALIMENTOS!$A$4:$A$47,0))*$C22/100,"") -> 0 | F22: =IFERROR(INDEX(ALIMENTOS!$E$4:$E$47,MATCH($B22,ALIMENTOS!$A$4:$A$47,0))*$C22/100,"") -> 0 | G22: =IFERROR(INDEX(ALIMENTOS!$F$4:$F$47,MATCH($B22,ALIMENTOS!$A$4:$A$47,0))*$C22/100,"") -> 7
B23: TOTAL DEL DÍA | D23: =SUM(D6:D22) -> 2767.44 | E23: =SUM(E6:E22) -> 219.72 | F23: =SUM(F6:F22) -> 318.84 | G23: =SUM(G6:G22) -> 69.514
B24: META | D24: =NUTRICION!$C$20 -> 2750 | E24: =NUTRICION!$C$23 -> 189 | F24: =NUTRICION!$C$25 -> 341 | G24: =NUTRICION!$C$24 -> 70
B25: DIFERENCIA | D25: =D23-D24 -> 17.44 | E25: =E23-E24 -> 30.72 | F25: =F23-F24 -> -22.16 | G25: =G23-G24 -> -0.486
A26: Intercambios permitidos sin recalcular: tilapia ⇄ lubina ⇄ dorada ⇄ pechuga de pollo (mismo peso). Arroz blanco ⇄ arroz integral ⇄ pasta integral (mismo peso seco). Batata ⇄ papa (multiplica el peso por 1.15 si usas papa).
A28: DÍA LIGERO — Sábado y Domingo (sin pesas)
A29: Comida | B29: Alimento | C29: Gramos | D29: kcal | E29: Proteína | F29: Carbs | G29: Grasa | H29: Nota
A30: Desayuno | B30: Huevo entero | C30: 150 | D30: =IFERROR(INDEX(ALIMENTOS!$C$4:$C$47,MATCH($B30,ALIMENTOS!$A$4:$A$47,0))*$C30/100,"") -> 214.5 | E30: =IFERROR(INDEX(ALIMENTOS!$D$4:$D$47,MATCH($B30,ALIMENTOS!$A$4:$A$47,0))*$C30/100,"") -> 18.9 | F30: =IFERROR(INDEX(ALIMENTOS!$E$4:$E$47,MATCH($B30,ALIMENTOS!$A$4:$A$47,0))*$C30/100,"") -> 1.05 | G30: =IFERROR(INDEX(ALIMENTOS!$F$4:$F$47,MATCH($B30,ALIMENTOS!$A$4:$A$47,0))*$C30/100,"") -> 14.85
A31: Desayuno | B31: Clara de huevo | C31: 200 | D31: =IFERROR(INDEX(ALIMENTOS!$C$4:$C$47,MATCH($B31,ALIMENTOS!$A$4:$A$47,0))*$C31/100,"") -> 104 | E31: =IFERROR(INDEX(ALIMENTOS!$D$4:$D$47,MATCH($B31,ALIMENTOS!$A$4:$A$47,0))*$C31/100,"") -> 21.8 | F31: =IFERROR(INDEX(ALIMENTOS!$E$4:$E$47,MATCH($B31,ALIMENTOS!$A$4:$A$47,0))*$C31/100,"") -> 1.4 | G31: =IFERROR(INDEX(ALIMENTOS!$F$4:$F$47,MATCH($B31,ALIMENTOS!$A$4:$A$47,0))*$C31/100,"") -> 0.4
A32: Desayuno | B32: Avena en hojuelas | C32: 50 | D32: =IFERROR(INDEX(ALIMENTOS!$C$4:$C$47,MATCH($B32,ALIMENTOS!$A$4:$A$47,0))*$C32/100,"") -> 194.5 | E32: =IFERROR(INDEX(ALIMENTOS!$D$4:$D$47,MATCH($B32,ALIMENTOS!$A$4:$A$47,0))*$C32/100,"") -> 8.45 | F32: =IFERROR(INDEX(ALIMENTOS!$E$4:$E$47,MATCH($B32,ALIMENTOS!$A$4:$A$47,0))*$C32/100,"") -> 33.15 | G32: =IFERROR(INDEX(ALIMENTOS!$F$4:$F$47,MATCH($B32,ALIMENTOS!$A$4:$A$47,0))*$C32/100,"") -> 3.45
A33: Desayuno | B33: Banana (guineo) | C33: 100 | D33: =IFERROR(INDEX(ALIMENTOS!$C$4:$C$47,MATCH($B33,ALIMENTOS!$A$4:$A$47,0))*$C33/100,"") -> 89 | E33: =IFERROR(INDEX(ALIMENTOS!$D$4:$D$47,MATCH($B33,ALIMENTOS!$A$4:$A$47,0))*$C33/100,"") -> 1.1 | F33: =IFERROR(INDEX(ALIMENTOS!$E$4:$E$47,MATCH($B33,ALIMENTOS!$A$4:$A$47,0))*$C33/100,"") -> 22.8 | G33: =IFERROR(INDEX(ALIMENTOS!$F$4:$F$47,MATCH($B33,ALIMENTOS!$A$4:$A$47,0))*$C33/100,"") -> 0.3
A34: Almuerzo | B34: Pechuga de pollo | C34: 250 | D34: =IFERROR(INDEX(ALIMENTOS!$C$4:$C$47,MATCH($B34,ALIMENTOS!$A$4:$A$47,0))*$C34/100,"") -> 300 | E34: =IFERROR(INDEX(ALIMENTOS!$D$4:$D$47,MATCH($B34,ALIMENTOS!$A$4:$A$47,0))*$C34/100,"") -> 56.25 | F34: =IFERROR(INDEX(ALIMENTOS!$E$4:$E$47,MATCH($B34,ALIMENTOS!$A$4:$A$47,0))*$C34/100,"") -> 0 | G34: =IFERROR(INDEX(ALIMENTOS!$F$4:$F$47,MATCH($B34,ALIMENTOS!$A$4:$A$47,0))*$C34/100,"") -> 6.5
A35: Almuerzo | B35: Arroz blanco | C35: 130 | D35: =IFERROR(INDEX(ALIMENTOS!$C$4:$C$47,MATCH($B35,ALIMENTOS!$A$4:$A$47,0))*$C35/100,"") -> 468 | E35: =IFERROR(INDEX(ALIMENTOS!$D$4:$D$47,MATCH($B35,ALIMENTOS!$A$4:$A$47,0))*$C35/100,"") -> 8.58 | F35: =IFERROR(INDEX(ALIMENTOS!$E$4:$E$47,MATCH($B35,ALIMENTOS!$A$4:$A$47,0))*$C35/100,"") -> 103.09 | G35: =IFERROR(INDEX(ALIMENTOS!$F$4:$F$47,MATCH($B35,ALIMENTOS!$A$4:$A$47,0))*$C35/100,"") -> 0.78
A36: Almuerzo | B36: Aguacate | C36: 30 | D36: =IFERROR(INDEX(ALIMENTOS!$C$4:$C$47,MATCH($B36,ALIMENTOS!$A$4:$A$47,0))*$C36/100,"") -> 48 | E36: =IFERROR(INDEX(ALIMENTOS!$D$4:$D$47,MATCH($B36,ALIMENTOS!$A$4:$A$47,0))*$C36/100,"") -> 0.6 | F36: =IFERROR(INDEX(ALIMENTOS!$E$4:$E$47,MATCH($B36,ALIMENTOS!$A$4:$A$47,0))*$C36/100,"") -> 2.55 | G36: =IFERROR(INDEX(ALIMENTOS!$F$4:$F$47,MATCH($B36,ALIMENTOS!$A$4:$A$47,0))*$C36/100,"") -> 4.41
A37: Almuerzo | B37: Ensalada verde mixta | C37: 200 | D37: =IFERROR(INDEX(ALIMENTOS!$C$4:$C$47,MATCH($B37,ALIMENTOS!$A$4:$A$47,0))*$C37/100,"") -> 34 | E37: =IFERROR(INDEX(ALIMENTOS!$D$4:$D$47,MATCH($B37,ALIMENTOS!$A$4:$A$47,0))*$C37/100,"") -> 2.4 | F37: =IFERROR(INDEX(ALIMENTOS!$E$4:$E$47,MATCH($B37,ALIMENTOS!$A$4:$A$47,0))*$C37/100,"") -> 6 | G37: =IFERROR(INDEX(ALIMENTOS!$F$4:$F$47,MATCH($B37,ALIMENTOS!$A$4:$A$47,0))*$C37/100,"") -> 0.4
A38: Almuerzo | B38: Aceite de oliva | C38: 7 | D38: =IFERROR(INDEX(ALIMENTOS!$C$4:$C$47,MATCH($B38,ALIMENTOS!$A$4:$A$47,0))*$C38/100,"") -> 61.88 | E38: =IFERROR(INDEX(ALIMENTOS!$D$4:$D$47,MATCH($B38,ALIMENTOS!$A$4:$A$47,0))*$C38/100,"") -> 0 | F38: =IFERROR(INDEX(ALIMENTOS!$E$4:$E$47,MATCH($B38,ALIMENTOS!$A$4:$A$47,0))*$C38/100,"") -> 0 | G38: =IFERROR(INDEX(ALIMENTOS!$F$4:$F$47,MATCH($B38,ALIMENTOS!$A$4:$A$47,0))*$C38/100,"") -> 7
A39: Merienda | B39: Proteína whey | C39: 30 | D39: =IFERROR(INDEX(ALIMENTOS!$C$4:$C$47,MATCH($B39,ALIMENTOS!$A$4:$A$47,0))*$C39/100,"") -> 120 | E39: =IFERROR(INDEX(ALIMENTOS!$D$4:$D$47,MATCH($B39,ALIMENTOS!$A$4:$A$47,0))*$C39/100,"") -> 24 | F39: =IFERROR(INDEX(ALIMENTOS!$E$4:$E$47,MATCH($B39,ALIMENTOS!$A$4:$A$47,0))*$C39/100,"") -> 3 | G39: =IFERROR(INDEX(ALIMENTOS!$F$4:$F$47,MATCH($B39,ALIMENTOS!$A$4:$A$47,0))*$C39/100,"") -> 1.5
A40: Merienda | B40: Mandarina | C40: 100 | D40: =IFERROR(INDEX(ALIMENTOS!$C$4:$C$47,MATCH($B40,ALIMENTOS!$A$4:$A$47,0))*$C40/100,"") -> 53 | E40: =IFERROR(INDEX(ALIMENTOS!$D$4:$D$47,MATCH($B40,ALIMENTOS!$A$4:$A$47,0))*$C40/100,"") -> 0.8 | F40: =IFERROR(INDEX(ALIMENTOS!$E$4:$E$47,MATCH($B40,ALIMENTOS!$A$4:$A$47,0))*$C40/100,"") -> 13.3 | G40: =IFERROR(INDEX(ALIMENTOS!$F$4:$F$47,MATCH($B40,ALIMENTOS!$A$4:$A$47,0))*$C40/100,"") -> 0.3
A41: Merienda | B41: Pistachos | C41: 20 | D41: =IFERROR(INDEX(ALIMENTOS!$C$4:$C$47,MATCH($B41,ALIMENTOS!$A$4:$A$47,0))*$C41/100,"") -> 112.4 | E41: =IFERROR(INDEX(ALIMENTOS!$D$4:$D$47,MATCH($B41,ALIMENTOS!$A$4:$A$47,0))*$C41/100,"") -> 4.04 | F41: =IFERROR(INDEX(ALIMENTOS!$E$4:$E$47,MATCH($B41,ALIMENTOS!$A$4:$A$47,0))*$C41/100,"") -> 5.44 | G41: =IFERROR(INDEX(ALIMENTOS!$F$4:$F$47,MATCH($B41,ALIMENTOS!$A$4:$A$47,0))*$C41/100,"") -> 9.06
A42: Cena | B42: Carne molida de res 90/10 | C42: 200 | D42: =IFERROR(INDEX(ALIMENTOS!$C$4:$C$47,MATCH($B42,ALIMENTOS!$A$4:$A$47,0))*$C42/100,"") -> 352 | E42: =IFERROR(INDEX(ALIMENTOS!$D$4:$D$47,MATCH($B42,ALIMENTOS!$A$4:$A$47,0))*$C42/100,"") -> 40 | F42: =IFERROR(INDEX(ALIMENTOS!$E$4:$E$47,MATCH($B42,ALIMENTOS!$A$4:$A$47,0))*$C42/100,"") -> 0 | G42: =IFERROR(INDEX(ALIMENTOS!$F$4:$F$47,MATCH($B42,ALIMENTOS!$A$4:$A$47,0))*$C42/100,"") -> 20 | H42: Peso CRUDO. Pide la magra.
...

Sheet GYM
A1: RUTINA — corte sin perder fuerza
A2: Principio del corte: la INTENSIDAD (el peso) se mantiene, el VOLUMEN (series accesorias) es lo que se recorta si la recuperación falla. Nunca al revés.
A4: DÍA 1 | B4: LUNES — Pecho / Tríceps / Antebrazo / Abdomen
A5: # | B5: Ejercicio | C5: Series | D5: Repeticiones | E5: RPE | F5: Descanso | G5: Mi carga (kg) | H5: Nota técnica
A6: 1 | B6: Calentamiento: 25 pechadas + movilidad de hombro | D6: 5 min | H6: Aquí van tus pechadas. No las hagas al despertar y otra vez en el gym.
A7: 2 | B7: Press de banca con barra | C7: 4 | D7: 4-6 | E7: 8 | F7: 3 min | H7: TU LEVANTAMIENTO ANCLA. Este peso no baja durante el corte. Si baja 2 semanas seguidas, el déficit es muy agresivo.
A8: 3 | B8: Press inclinado con mancuernas | C8: 3 | D8: 8-10 | E8: 8 | F8: 2 min | H8: Inclinación 30°, no más.
A9: 4 | B9: Fondos en paralelas | C9: 3 | D9: 8-10 | E9: 8 | F9: 2 min | H9: Lastrados si haces más de 12 limpias. Pecho ligeramente inclinado hacia adelante.
A10: 5 | B10: Cruce de poleas (aperturas) | C10: 3 | D10: 12-15 | E10: 9 | F10: 60 s | H10: Aquí sí llegas cerca del fallo. Es aislamiento, es seguro.
A11: 6 | B11: Extensión de tríceps en polea (barra recta) | C11: 3 | D11: 10-12 | E11: 8 | F11: 90 s | H11: Codos pegados al torso.
A12: 7 | B12: Extensión sobre cabeza con cuerda | C12: 3 | D12: 12-15 | E12: 9 | F12: 60 s | H12: Trabaja la cabeza larga del tríceps — la que da volumen al brazo.
A13: 8 | B13: Curl de muñeca con barra | C13: 3 | D13: 15-20 | E13: 9 | F13: 45 s | H13: Antebrazo. Rango completo, peso ligero.
A14: 9 | B14: Paseo del granjero (farmer's carry) | C14: 3 | D14: 45 seg | E14: 8 | F14: 60 s | H14: Agarre + antebrazo + core en un solo movimiento.
A15: 10 | B15: Plancha frontal | C15: 3 | D15: 45-60 seg | E15: 8 | F15: 45 s
A16: 11 | B16: Dead bug con banda | C16: 3 | D16: 10/lado | E16: 8 | F16: 45 s | H16: Anti-extensión. Sustituye la elevación de piernas: no carga el disco en flexión.
A17: 12 | B17: CARDIO: 15 min Z2 en cinta o elíptica | D17: 15 min | H17: Frecuencia conversacional. No corras aquí — el correr largo va el sábado.
A19: DÍA 2 | B19: MARTES — Espalda / Bíceps / Deltoide posterior / Abdomen
A20: # | B20: Ejercicio | C20: Series | D20: Repeticiones | E20: RPE | F20: Descanso | G20: Mi carga (kg) | H20: Nota técnica
A21: 1 | B21: Calentamiento: 2x8 dominadas + face pull ligero | D21: 5 min | H21: Aquí van tus dominadas. Meta: llegar a 25-50 acumuladas en la sesión sumando series.
A22: 2 | B22: Dominadas lastradas | C22: 4 | D22: 5-8 | E22: 8 | F22: 3 min | H22: TU LEVANTAMIENTO ANCLA de tracción. Si no llegas a 5 lastradas, hazlas al peso corporal 4x8-10.
A23: 3 | B23: Remo en máquina con pecho apoyado | C23: 4 | D23: 8-12 | E23: 8 | F23: 2.5 min | H23: TU LEVANTAMIENTO ANCLA de espalda: 5 discos de 45 lb por lado x12. El pecho apoyado quita la carga del erector lumbar — por eso reemplaza al remo con barra inclinado.
A24: 4 | B24: Jalón al pecho agarre neutro | C24: 3 | D24: 10-12 | E24: 8 | F24: 90 s
A25: 5 | B25: Remo en polea baja | C25: 3 | D25: 10-12 | E25: 8 | F25: 90 s | H25: Aprieta 1 segundo en la contracción.
A26: 6 | B26: Face pull | C26: 3 | D26: 15-20 | E26: 9 | F26: 60 s | H26: Salud de hombro. No lo saltes — con este volumen de press lo vas a necesitar.
A27: 7 | B27: Pájaros / elevación posterior | C27: 3 | D27: 15-20 | E27: 9 | F27: 60 s | H27: Deltoide posterior.
A28: 8 | B28: Curl con barra Z | C28: 3 | D28: 8-10 | E28: 8 | F28: 90 s
A29: 9 | B29: Curl martillo | C29: 3 | D29: 10-12 | E29: 8 | F29: 60 s | H29: También pega antebrazo (braquiorradial).
A30: 10 | B30: Press Pallof en polea | C30: 3 | D30: 12/lado | E30: 8 | F30: 45 s | H30: Anti-rotación. Reemplaza la rueda abdominal, que carga el disco en extensión bajo tensión.
A31: 11 | B31: Paseo maleta (suitcase carry) | C31: 3 | D31: 40 seg/lado | E31: 8 | F31: 45 s | H31: Anti-flexión lateral. Transfiere al swing de softball sin rotar la columna bajo carga.
A32: 12 | B32: CARDIO: 15 min Z2 | D32: 15 min
A34: DÍA 3 | B34: MIÉRCOLES — Pecho + Espalda / Hombro / Abdomen (superseries)
A35: # | B35: Ejercicio | C35: Series | D35: Repeticiones | E35: RPE | F35: Descanso | G35: Mi carga (kg) | H35: Nota técnica
A36: 1 | B36: Sesión corta a propósito: 50 min. Hoy el cardio es softball + natación.
A37: 2 | B37: A1 Press inclinado con mancuernas | C37: 4 | D37: 8-10 | E37: 8 | F37: 0 s | H37: Superserie con A2: no descansas entre A1 y A2.
A38: 3 | B38: A2 Remo con mancuerna a una mano | C38: 4 | D38: 8-10/lado | E38: 8 | F38: 90 s | H38: Descansas 90 s después de completar A1+A2.
A39: 4 | B39: B1 Press militar de pie con barra | C39: 3 | D39: 6-8 | E39: 8 | F39: 0 s | H39: TU LEVANTAMIENTO ANCLA de hombro. De pie, no sentado.
A40: 5 | B40: B2 Jalón al pecho agarre ancho | C40: 3 | D40: 10-12 | E40: 8 | F40: 90 s
A41: 6 | B41: C1 Elevaciones laterales | C41: 3 | D41: 15-20 | E41: 9 | F41: 0 s | H41: Deltoide medio — el que da ancho a la silueta.
A42: 7 | B42: C2 Pechadas hasta 2 reps del fallo | C42: 3 | D42: máx | E42: 9 | F42: 60 s | H42: Aquí completas el volumen de pechadas del día.
A43: 8 | B43: Elevación frontal en polea | C43: 3 | D43: 12-15 | E43: 8 | F43: 60 s
...

Sheet PROGRESION
A1: PROGRESIÓN 12 SEMANAS — calculada desde tus PR reales
A2: En déficit calórico, MANTENER la carga ya es éxito. Los incrementos de abajo son objetivo, no obligación. Si mantienes los números de la semana 1 durante 12 semanas y bajas 8 kg, el corte fue perfecto.
A4: TUS PR DECLARADOS (03/09/2026)
B5: Levantamiento | C5: PR declarado | D5: 1RM estimado (lb) | K5: Nota
B6: Press de banca | C6: 225 lb x 5 | D6: 260 | K6: Epley. Tu serie de trabajo 4-6 reps vive entre 215 y 240 lb.
B7: Peso muerto convencional | C7: 315 lb x 3 | D7: 340 | K7: CONDICIONAL — con hernias discales requiere autorización. La progresión de abajo usa RDL con barra hexagonal o mancuernas.
B8: Remo en máquina | C8: 5 discos/lado x 12 | D8: — | K8: Tu 12RM. Es tu ancla de tracción horizontal.
B9: Prensa de piernas | C9: 800 lb | D9: — | K9: Tu ancla de pierna, en sustitución de la sentadilla.
B10: Extensión de cuádriceps | C10: 210 lb (stack completo) | D10: — | K10: Ya lo maxeas: la progresión ahora es por tempo y pausa, no por peso.
B11: Dominadas | C11: 10-12 máx / 5-8 habitual | D11: — | K11: Objetivo semana 12: 4x10 limpias o 5 reps con +25 lb.
B12: Pechadas | C12: 50 máx / 20-25 habitual | D12: — | K12: Objetivo semana 12: volver a 50 en una serie.
B13: Press militar de pie | C13: PENDIENTE | D13: — | K13: Anótalo la primera semana y te recalculo el bloque de hombro.
A15: CALENDARIO DE CARGAS — 3 bloques de 4 semanas
A16: Semana | B16: Bloque | C16: Press banca (serie tope) | D16: Banca (backoff) | E16: Remo máquina (discos/lado) | F16: Prensa piernas | G16: Empuje cadera | H16: RDL hex/mancuernas | I16: Dominadas | J16: Pechadas (Día 3) | K16: Enfoque de la semana
A17: 1 | B17: 1 | C17: 215 lb x 6 | D17: 3x8 @ 175 | E17: 4.0 x 12 | F17: 590 x 8 | G17: 155 x 10 | H17: 165 x 10 | I17: 5 x 5 | J17: 3 x 22 | K17: Acumulación. Semana fácil a propósito: estás entrando en déficit.
A18: 2 | B18: 1 | C18: 225 lb x 5 | D18: 3x8 @ 185 | E18: 4.5 x 10 | F18: 640 x 6 | G18: 175 x 10 | H18: 185 x 8 | I18: 5 x 6 | J18: 3 x 25 | K18: Igualas tu PR de banca. Si sale limpio, el déficit está bien calibrado.
A19: 3 | B19: 1 | C19: 235 lb x 4 | D19: 3x8 @ 190 | E19: 5.0 x 10 | F19: 680 x 6 | G19: 195 x 8 | H19: 205 x 8 | I19: 4 x 8 | J19: 3 x 28 | K19: Pico del bloque. RPE 8.5, nunca al fallo.
A20: 4 | B20: 1 | C20: 185 lb x 5 (2 series) | D20: — | E20: 3.0 x 12 | F20: 450 x 10 | G20: 135 x 10 | H20: 135 x 10 | I20: 3 x 5 | J20: 3 x 20 | K20: DELOAD. No lo saltes. Con 4 días de pesas + baloncesto 2x + natación en déficit, esta semana es lo que evita la lesión.
A21: 5 | B21: 2 | C21: 220 lb x 6 | D21: 3x8 @ 180 | E21: 4.5 x 12 | F21: 610 x 8 | G21: 175 x 10 | H21: 175 x 10 | I21: 5 x 6 | J21: 3 x 30 | K21: Reinicio del bloque 5 lb arriba. Primera medición real de si mantienes fuerza.
A22: 6 | B22: 2 | C22: 230 lb x 5 | D22: 3x8 @ 190 | E22: 5.0 x 10 | F22: 660 x 6 | G22: 195 x 10 | H22: 195 x 8 | I22: 5 x 7 | J22: 3 x 33 | K22: Superas el PR en volumen.
A23: 7 | B23: 2 | C23: 240 lb x 4 | D23: 3x8 @ 195 | E23: 5.0 x 12 | F23: 700 x 6 | G23: 215 x 8 | H23: 215 x 8 | I23: 4 x 9 | J23: 3 x 36 | K23: Pico. Si esta semana falla, revisa sueño antes que calorías.
A24: 8 | B24: 2 | C24: 190 lb x 5 (2 series) | D24: — | E24: 3.5 x 12 | F24: 470 x 10 | G24: 145 x 10 | H24: 145 x 10 | I24: 3 x 6 | J24: 3 x 22 | K24: DELOAD + re-medición: pésate, mide cintura, repite fotos.
A25: 9 | B25: 3 | C25: 225 lb x 6 | D25: 3x8 @ 185 | E25: 5.0 x 12 | F25: 630 x 8 | G25: 195 x 10 | H25: 185 x 10 | I25: 5 x 7 | J25: 3 x 38 | K25: Bloque final. Aquí el déficit ya pesa: prioriza la serie tope, recorta accesorios si hace falta.
A26: 10 | B26: 3 | C26: 235 lb x 5 | D26: 3x8 @ 195 | E26: 5.5 x 10 | F26: 680 x 6 | G26: 215 x 10 | H26: 205 x 8 | I26: 5 x 8 | J26: 3 x 42 | K26: PR de volumen en banca: 235x5 supera 225x5.
A27: 11 | B27: 3 | C27: 245 lb x 4 | D27: 3x8 @ 200 | E27: 5.5 x 12 | F27: 720 x 6 | G27: 235 x 8 | H27: 225 x 8 | I27: 4 x 10 | J27: 3 x 45 | K27: Pico del ciclo.
A28: 12 | B28: 3 | C28: DELOAD + retest | D28: — | E28: 4.0 x 12 | F28: 490 x 10 | G28: 155 x 10 | H28: 155 x 10 | I28: Test máximo | J28: Test 50 reps | K28: Semana de prueba: banca a 5 reps máximo, dominadas al máximo, pechadas a 50. Y perfil lipídico de control.
A30: REGLAS DE LECTURA
A31: Si fallas la serie tope dos semanas seguidas: el problema es sueño o calorías, en ese orden. Revisa el DASHBOARD antes de tocar el gimnasio.
A32: Si la serie tope sale a RPE 6-7 (te sobraban 3+ reps): sube 10 lb la semana siguiente. El plan es un piso, no un techo.
A33: Nunca sustituyas el deload por 'una semana ligera improvisada'. Está en el calendario por la misma razón que un cierre contable: si no se agenda, no ocurre.
A34: Extensión de cuádriceps y máquinas de aductor/abductor: ya estás en el stack completo. Tu progresión ahí es tempo (3 seg bajando), pausa (1-2 seg) y series adicionales — no peso.

Sheet BITACORA
A1: BITÁCORA DIARIA — llena solo las celdas amarillas
A2: PESOS → | D2: 8 | E2: 4 | F2: 6 | G2: 15 | H2: 6 | I2: 6 | J2: 3 | K2: 3 | R2: 12 | S2: 10 | T2: 8 | U2: 13 | V2: 6 | Y2: Suma = 100 puntos por día
A3: Fecha | B3: Día | C3: Tipo | D3: Levantar 5:00 | E3: Cama+bulto | F3: Briefing | G3: Entrenamiento | H3: Cardio 30' | I3: Rosario | J3: Lectura 20' | K3: Supl. | L3: Proteína (g) | M3: Calorías | N3: Agua (L) | O3: Estudio (min) | P3: Sueño (h) | Q3: Meta kcal | R3: ✓Proteína | S3: ✓Calorías | T3: ✓Agua | U3: ✓Estudio | V3: ✓Sueño | W3: PUNTAJE | X3: % | Y3: Notas
A4: 46272 | B4: Lunes | C4: ENTRENO | D4: 1 | E4: 1 | F4: 1 | G4: 1 | H4: 1 | I4: 1 | J4: 0 | K4: 1 | L4: 212 | M4: 2710 | N4: 5.2 | O4: 60 | P4: 6 | Q4: =IF($C4="AYUNO",0,IF($C4="LIGERO",NUTRICION!$C$21,NUTRICION!$C$20)) -> 2750 | R4: =IF(COUNTA($D4:$P4)=0,0,IF($C4="AYUNO",IF(N($M4)<=200,1,0),IF(N($L4)>=NUTRICION!$C$23,1,0))) -> 1 | S4: =IF(COUNTA($D4:$P4)=0,0,IF($C4="AYUNO",IF(N($M4)<=200,1,0),IF(AND(N($M4)>=$Q4-150,N($M4)<=$Q4+150),1,0))) -> 1 | T4: =IF(COUNTA($D4:$P4)=0,0,IF(N($N4)>=NUTRICION!$C$27,1,0)) -> 1 | U4: =IF(COUNTA($D4:$P4)=0,0,IF(N($O4)>=NUTRICION!$C$30,1,0)) -> 0 | V4: =IF(COUNTA($D4:$P4)=0,0,IF(N($P4)>=NUTRICION!$C$29,1,0)) -> 0 | W4: =IF(COUNTA($D4:$P4)=0,"",SUMPRODUCT($D$2:$K$2,$D4:$K4)+SUMPRODUCT($R$2:$V$2,$R4:$V4)) -> 78 | X4: =IF($W4="","",$W4/100) -> 0.78 | Y4: EJEMPLO — bórralo. Lunes de baloncesto: estudio corto y sueño corto, todo lo demás en orden.
A5: 46273 | B5: Martes | C5: ENTRENO | Q5: =IF($C5="AYUNO",0,IF($C5="LIGERO",NUTRICION!$C$21,NUTRICION!$C$20)) -> 2750 | R5: =IF(COUNTA($D5:$P5)=0,0,IF($C5="AYUNO",IF(N($M5)<=200,1,0),IF(N($L5)>=NUTRICION!$C$23,1,0))) -> 0 | S5: =IF(COUNTA($D5:$P5)=0,0,IF($C5="AYUNO",IF(N($M5)<=200,1,0),IF(AND(N($M5)>=$Q5-150,N($M5)<=$Q5+150),1,0))) -> 0 | T5: =IF(COUNTA($D5:$P5)=0,0,IF(N($N5)>=NUTRICION!$C$27,1,0)) -> 0 | U5: =IF(COUNTA($D5:$P5)=0,0,IF(N($O5)>=NUTRICION!$C$30,1,0)) -> 0 | V5: =IF(COUNTA($D5:$P5)=0,0,IF(N($P5)>=NUTRICION!$C$29,1,0)) -> 0 | W5: =IF(COUNTA($D5:$P5)=0,"",SUMPRODUCT($D$2:$K$2,$D5:$K5)+SUMPRODUCT($R$2:$V$2,$R5:$V5)) | X5: =IF($W5="","",$W5/100)
A6: 46274 | B6: Miércoles | C6: ENTRENO | Q6: =IF($C6="AYUNO",0,IF($C6="LIGERO",NUTRICION!$C$21,NUTRICION!$C$20)) -> 2750 | R6: =IF(COUNTA($D6:$P6)=0,0,IF($C6="AYUNO",IF(N($M6)<=200,1,0),IF(N($L6)>=NUTRICION!$C$23,1,0))) -> 0 | S6: =IF(COUNTA($D6:$P6)=0,0,IF($C6="AYUNO",IF(N($M6)<=200,1,0),IF(AND(N($M6)>=$Q6-150,N($M6)<=$Q6+150),1,0))) -> 0 | T6: =IF(COUNTA($D6:$P6)=0,0,IF(N($N6)>=NUTRICION!$C$27,1,0)) -> 0 | U6: =IF(COUNTA($D6:$P6)=0,0,IF(N($O6)>=NUTRICION!$C$30,1,0)) -> 0 | V6: =IF(COUNTA($D6:$P6)=0,0,IF(N($P6)>=NUTRICION!$C$29,1,0)) -> 0 | W6: =IF(COUNTA($D6:$P6)=0,"",SUMPRODUCT($D$2:$K$2,$D6:$K6)+SUMPRODUCT($R$2:$V$2,$R6:$V6)) | X6: =IF($W6="","",$W6/100)
A7: 46275 | B7: Jueves | C7: ENTRENO | Q7: =IF($C7="AYUNO",0,IF($C7="LIGERO",NUTRICION!$C$21,NUTRICION!$C$20)) -> 2750 | R7: =IF(COUNTA($D7:$P7)=0,0,IF($C7="AYUNO",IF(N($M7)<=200,1,0),IF(N($L7)>=NUTRICION!$C$23,1,0))) -> 0 | S7: =IF(COUNTA($D7:$P7)=0,0,IF($C7="AYUNO",IF(N($M7)<=200,1,0),IF(AND(N($M7)>=$Q7-150,N($M7)<=$Q7+150),1,0))) -> 0 | T7: =IF(COUNTA($D7:$P7)=0,0,IF(N($N7)>=NUTRICION!$C$27,1,0)) -> 0 | U7: =IF(COUNTA($D7:$P7)=0,0,IF(N($O7)>=NUTRICION!$C$30,1,0)) -> 0 | V7: =IF(COUNTA($D7:$P7)=0,0,IF(N($P7)>=NUTRICION!$C$29,1,0)) -> 0 | W7: =IF(COUNTA($D7:$P7)=0,"",SUMPRODUCT($D$2:$K$2,$D7:$K7)+SUMPRODUCT($R$2:$V$2,$R7:$V7)) | X7: =IF($W7="","",$W7/100)
A8: 46276 | B8: Viernes | C8: AYUNO | Q8: =IF($C8="AYUNO",0,IF($C8="LIGERO",NUTRICION!$C$21,NUTRICION!$C$20)) -> 0 | R8: =IF(COUNTA($D8:$P8)=0,0,IF($C8="AYUNO",IF(N($M8)<=200,1,0),IF(N($L8)>=NUTRICION!$C$23,1,0))) -> 0 | S8: =IF(COUNTA($D8:$P8)=0,0,IF($C8="AYUNO",IF(N($M8)<=200,1,0),IF(AND(N($M8)>=$Q8-150,N($M8)<=$Q8+150),1,0))) -> 0 | T8: =IF(COUNTA($D8:$P8)=0,0,IF(N($N8)>=NUTRICION!$C$27,1,0)) -> 0 | U8: =IF(COUNTA($D8:$P8)=0,0,IF(N($O8)>=NUTRICION!$C$30,1,0)) -> 0 | V8: =IF(COUNTA($D8:$P8)=0,0,IF(N($P8)>=NUTRICION!$C$29,1,0)) -> 0 | W8: =IF(COUNTA($D8:$P8)=0,"",SUMPRODUCT($D$2:$K$2,$D8:$K8)+SUMPRODUCT($R$2:$V$2,$R8:$V8)) | X8: =IF($W8="","",$W8/100)
A9: 46277 | B9: Sábado | C9: LIGERO | Q9: =IF($C9="AYUNO",0,IF($C9="LIGERO",NUTRICION!$C$21,NUTRICION!$C$20)) -> 2450 | R9: =IF(COUNTA($D9:$P9)=0,0,IF($C9="AYUNO",IF(N($M9)<=200,1,0),IF(N($L9)>=NUTRICION!$C$23,1,0))) -> 0 | S9: =IF(COUNTA($D9:$P9)=0,0,IF($C9="AYUNO",IF(N($M9)<=200,1,0),IF(AND(N($M9)>=$Q9-150,N($M9)<=$Q9+150),1,0))) -> 0 | T9: =IF(COUNTA($D9:$P9)=0,0,IF(N($N9)>=NUTRICION!$C$27,1,0)) -> 0 | U9: =IF(COUNTA($D9:$P9)=0,0,IF(N($O9)>=NUTRICION!$C$30,1,0)) -> 0 | V9: =IF(COUNTA($D9:$P9)=0,0,IF(N($P9)>=NUTRICION!$C$29,1,0)) -> 0 | W9: =IF(COUNTA($D9:$P9)=0,"",SUMPRODUCT($D$2:$K$2,$D9:$K9)+SUMPRODUCT($R$2:$V$2,$R9:$V9)) | X9: =IF($W9="","",$W9/100)
A10: 46278 | B10: Domingo | C10: LIGERO | Q10: =IF($C10="AYUNO",0,IF($C10="LIGERO",NUTRICION!$C$21,NUTRICION!$C$20)) -> 2450 | R10: =IF(COUNTA($D10:$P10)=0,0,IF($C10="AYUNO",IF(N($M10)<=200,1,0),IF(N($L10)>=NUTRICION!$C$23,1,0))) -> 0 | S10: =IF(COUNTA($D10:$P10)=0,0,IF($C10="AYUNO",IF(N($M10)<=200,1,0),IF(AND(N($M10)>=$Q10-150,N($M10)<=$Q10+150),1,0))) -> 0 | T10: =IF(COUNTA($D10:$P10)=0,0,IF(N($N10)>=NUTRICION!$C$27,1,0)) -> 0 | U10: =IF(COUNTA($D10:$P10)=0,0,IF(N($O10)>=NUTRICION!$C$30,1,0)) -> 0 | V10: =IF(COUNTA($D10:$P10)=0,0,IF(N($P10)>=NUTRICION!$C$29,1,0)) -> 0 | W10: =IF(COUNTA($D10:$P10)=0,"",SUMPRODUCT($D$2:$K$2,$D10:$K10)+SUMPRODUCT($R$2:$V$2,$R10:$V10)) | X10: =IF($W10="","",$W10/100)
A11: 46279 | B11: Lunes | C11: ENTRENO | Q11: =IF($C11="AYUNO",0,IF($C11="LIGERO",NUTRICION!$C$21,NUTRICION!$C$20)) -> 2750 | R11: =IF(COUNTA($D11:$P11)=0,0,IF($C11="AYUNO",IF(N($M11)<=200,1,0),IF(N($L11)>=NUTRICION!$C$23,1,0))) -> 0 | S11: =IF(COUNTA($D11:$P11)=0,0,IF($C11="AYUNO",IF(N($M11)<=200,1,0),IF(AND(N($M11)>=$Q11-150,N($M11)<=$Q11+150),1,0))) -> 0 | T11: =IF(COUNTA($D11:$P11)=0,0,IF(N($N11)>=NUTRICION!$C$27,1,0)) -> 0 | U11: =IF(COUNTA($D11:$P11)=0,0,IF(N($O11)>=NUTRICION!$C$30,1,0)) -> 0 | V11: =IF(COUNTA($D11:$P11)=0,0,IF(N($P11)>=NUTRICION!$C$29,1,0)) -> 0 | W11: =IF(COUNTA($D11:$P11)=0,"",SUMPRODUCT($D$2:$K$2,$D11:$K11)+SUMPRODUCT($R$2:$V$2,$R11:$V11)) | X11: =IF($W11="","",$W11/100)
A12: 46280 | B12: Martes | C12: ENTRENO | Q12: =IF($C12="AYUNO",0,IF($C12="LIGERO",NUTRICION!$C$21,NUTRICION!$C$20)) -> 2750 | R12: =IF(COUNTA($D12:$P12)=0,0,IF($C12="AYUNO",IF(N($M12)<=200,1,0),IF(N($L12)>=NUTRICION!$C$23,1,0))) -> 0 | S12: =IF(COUNTA($D12:$P12)=0,0,IF($C12="AYUNO",IF(N($M12)<=200,1,0),IF(AND(N($M12)>=$Q12-150,N($M12)<=$Q12+150),1,0))) -> 0 | T12: =IF(COUNTA($D12:$P12)=0,0,IF(N($N12)>=NUTRICION!$C$27,1,0)) -> 0 | U12: =IF(COUNTA($D12:$P12)=0,0,IF(N($O12)>=NUTRICION!$C$30,1,0)) -> 0 | V12: =IF(COUNTA($D12:$P12)=0,0,IF(N($P12)>=NUTRICION!$C$29,1,0)) -> 0 | W12: =IF(COUNTA($D12:$P12)=0,"",SUMPRODUCT($D$2:$K$2,$D12:$K12)+SUMPRODUCT($R$2:$V$2,$R12:$V12)) | X12: =IF($W12="","",$W12/100)
A13: 46281 | B13: Miércoles | C13: ENTRENO | Q13: =IF($C13="AYUNO",0,IF($C13="LIGERO",NUTRICION!$C$21,NUTRICION!$C$20)) -> 2750 | R13: =IF(COUNTA($D13:$P13)=0,0,IF($C13="AYUNO",IF(N($M13)<=200,1,0),IF(N($L13)>=NUTRICION!$C$23,1,0))) -> 0 | S13: =IF(COUNTA($D13:$P13)=0,0,IF($C13="AYUNO",IF(N($M13)<=200,1,0),IF(AND(N($M13)>=$Q13-150,N($M13)<=$Q13+150),1,0))) -> 0 | T13: =IF(COUNTA($D13:$P13)=0,0,IF(N($N13)>=NUTRICION!$C$27,1,0)) -> 0 | U13: =IF(COUNTA($D13:$P13)=0,0,IF(N($O13)>=NUTRICION!$C$30,1,0)) -> 0 | V13: =IF(COUNTA($D13:$P13)=0,0,IF(N($P13)>=NUTRICION!$C$29,1,0)) -> 0 | W13: =IF(COUNTA($D13:$P13)=0,"",SUMPRODUCT($D$2:$K$2,$D13:$K13)+SUMPRODUCT($R$2:$V$2,$R13:$V13)) | X13: =IF($W13="","",$W13/100)
A14: 46282 | B14: Jueves | C14: ENTRENO | Q14: =IF($C14="AYUNO",0,IF($C14="LIGERO",NUTRICION!$C$21,NUTRICION!$C$20)) -> 2750 | R14: =IF(COUNTA($D14:$P14)=0,0,IF($C14="AYUNO",IF(N($M14)<=200,1,0),IF(N($L14)>=NUTRICION!$C$23,1,0))) -> 0 | S14: =IF(COUNTA($D14:$P14)=0,0,IF($C14="AYUNO",IF(N($M14)<=200,1,0),IF(AND(N($M14)>=$Q14-150,N($M14)<=$Q14+150),1,0))) -> 0 | T14: =IF(COUNTA($D14:$P14)=0,0,IF(N($N14)>=NUTRICION!$C$27,1,0)) -> 0 | U14: =IF(COUNTA($D14:$P14)=0,0,IF(N($O14)>=NUTRICION!$C$30,1,0)) -> 0 | V14: =IF(COUNTA($D14:$P14)=0,0,IF(N($P14)>=NUTRICION!$C$29,1,0)) -> 0 | W14: =IF(COUNTA($D14:$P14)=0,"",SUMPRODUCT($D$2:$K$2,$D14:$K14)+SUMPRODUCT($R$2:$V$2,$R14:$V14)) | X14: =IF($W14="","",$W14/100)
A15: 46283 | B15: Viernes | C15: AYUNO | Q15: =IF($C15="AYUNO",0,IF($C15="LIGERO",NUTRICION!$C$21,NUTRICION!$C$20)) -> 0 | R15: =IF(COUNTA($D15:$P15)=0,0,IF($C15="AYUNO",IF(N($M15)<=200,1,0),IF(N($L15)>=NUTRICION!$C$23,1,0))) -> 0 | S15: =IF(COUNTA($D15:$P15)=0,0,IF($C15="AYUNO",IF(N($M15)<=200,1,0),IF(AND(N($M15)>=$Q15-150,N($M15)<=$Q15+150),1,0))) -> 0 | T15: =IF(COUNTA($D15:$P15)=0,0,IF(N($N15)>=NUTRICION!$C$27,1,0)) -> 0 | U15: =IF(COUNTA($D15:$P15)=0,0,IF(N($O15)>=NUTRICION!$C$30,1,0)) -> 0 | V15: =IF(COUNTA($D15:$P15)=0,0,IF(N($P15)>=NUTRICION!$C$29,1,0)) -> 0 | W15: =IF(COUNTA($D15:$P15)=0,"",SUMPRODUCT($D$2:$K$2,$D15:$K15)+SUMPRODUCT($R$2:$V$2,$R15:$V15)) | X15: =IF($W15="","",$W15/100)
A16: 46284 | B16: Sábado | C16: LIGERO | Q16: =IF($C16="AYUNO",0,IF($C16="LIGERO",NUTRICION!$C$21,NUTRICION!$C$20)) -> 2450 | R16: =IF(COUNTA($D16:$P16)=0,0,IF($C16="AYUNO",IF(N($M16)<=200,1,0),IF(N($L16)>=NUTRICION!$C$23,1,0))) -> 0 | S16: =IF(COUNTA($D16:$P16)=0,0,IF($C16="AYUNO",IF(N($M16)<=200,1,0),IF(AND(N($M16)>=$Q16-150,N($M16)<=$Q16+150),1,0))) -> 0 | T16: =IF(COUNTA($D16:$P16)=0,0,IF(N($N16)>=NUTRICION!$C$27,1,0)) -> 0 | U16: =IF(COUNTA($D16:$P16)=0,0,IF(N($O16)>=NUTRICION!$C$30,1,0)) -> 0 | V16: =IF(COUNTA($D16:$P16)=0,0,IF(N($P16)>=NUTRICION!$C$29,1,0)) -> 0 | W16: =IF(COUNTA($D16:$P16)=0,"",SUMPRODUCT($D$2:$K$2,$D16:$K16)+SUMPRODUCT($R$2:$V$2,$R16:$V16)) | X16: =IF($W16="","",$W16/100)
... A94: 46362 | B94: Domingo | C94: LIGERO | Q94: =IF($C94="AYUNO",0,IF($C94="LIGERO",NUTRICION!$C$21,NUTRICION!$C$20)) -> 2450 | R94: =IF(COUNTA($D94:$P94)=0,0,IF($C94="AYUNO",IF(N($M94)<=200,1,0),IF(N($L94)>=NUTRICION!$C$23,1,0))) -> 0 | S94: =IF(COUNTA($D94:$P94)=0,0,IF($C94="AYUNO",IF(N($M94)<=200,1,0),IF(AND(N($M94)>=$Q94-150,N($M94)<=$Q94+150),1,0))) -> 0 | T94: =IF(COUNTA($D94:$P94)=0,0,IF(N($N94)>=NUTRICION!$C$27,1,0)) -> 0 | U94: =IF(COUNTA($D94:$P94)=0,0,IF(N($O94)>=NUTRICION!$C$30,1,0)) -> 0 | V94: =IF(COUNTA($D94:$P94)=0,0,IF(N($P94)>=NUTRICION!$C$29,1,0)) -> 0 | W94: =IF(COUNTA($D94:$P94)=0,"",SUMPRODUCT($D$2:$K$2,$D94:$K94)+SUMPRODUCT($R$2:$V$2,$R94:$V94)) | X94: =IF($W94="","",$W94/100)

Sheet DASHBOARD
A1: ESTADO DE RESULTADOS DE LA DISCIPLINA
B2: Mismo principio que un P&L: cada hábito es un renglón, y el margen final te dice si el mes cerró en utilidad o en pérdida.
B4: RESUMEN EJECUTIVO
B5: Días registrados | C5: =COUNT(BITACORA!$W$4:$W$200) -> 1
B6: Puntaje promedio (de 100) | C6: =IFERROR(AVERAGE(BITACORA!$W$4:$W$200),0) -> 78
B7: Margen de cumplimiento acumulado | C7: =IFERROR(AVERAGE(BITACORA!$W$4:$W$200)/100,0) -> 0.78
B8: Últimos 7 días | C8: =IFERROR(AVERAGEIFS(BITACORA!$W$4:$W$200,BITACORA!$A$4:$A$200,">="&TODAY()-6,BITACORA!$A$4:$A$200,"<="&TODAY())/100,"sin datos") -> sin datos
B9: Días con 80+ puntos | C9: =COUNTIF(BITACORA!$W$4:$W$200,">=80") -> 0
B10: Días con menos de 60 puntos | C10: =COUNTIF(BITACORA!$W$4:$W$200,"<60") -> 0
B12: DESGLOSE POR RENGLÓN
B13: Renglón | C13: Puntos logrados | D13: Puntos posibles | E13: Adherencia | F13: Diagnóstico
B14: DISCIPLINA BASE
B15: Levantarse 5:00 | C15: =SUM(BITACORA!$D$4:$D$200)*BITACORA!$D$2 -> 8 | D15: =COUNT(BITACORA!$W$4:$W$200)*BITACORA!$D$2 -> 8 | E15: =IFERROR($C15/$D15,"") -> 1 | F15: =IF($D15=0,"",IF($E15>=0.9,"Sólido",IF($E15>=0.75,"Aceptable",IF($E15>=0.5,"Aquí se está fugando el resultado","Renglón crítico")))) -> Sólido
B16: Cama + bulto | C16: =SUM(BITACORA!$E$4:$E$200)*BITACORA!$E$2 -> 4 | D16: =COUNT(BITACORA!$W$4:$W$200)*BITACORA!$E$2 -> 4 | E16: =IFERROR($C16/$D16,"") -> 1 | F16: =IF($D16=0,"",IF($E16>=0.9,"Sólido",IF($E16>=0.75,"Aceptable",IF($E16>=0.5,"Aquí se está fugando el resultado","Renglón crítico")))) -> Sólido
B17: Briefing de mercado | C17: =SUM(BITACORA!$F$4:$F$200)*BITACORA!$F$2 -> 6 | D17: =COUNT(BITACORA!$W$4:$W$200)*BITACORA!$F$2 -> 6 | E17: =IFERROR($C17/$D17,"") -> 1 | F17: =IF($D17=0,"",IF($E17>=0.9,"Sólido",IF($E17>=0.75,"Aceptable",IF($E17>=0.5,"Aquí se está fugando el resultado","Renglón crítico")))) -> Sólido
B18: Subtotal DISCIPLINA BASE | C18: =SUM(C15:C17) -> 18 | D18: =SUM(D15:D17) -> 18 | E18: =IFERROR($C18/$D18,"") -> 1
B20: ENTRENAMIENTO
B21: Sesión de entrenamiento | C21: =SUM(BITACORA!$G$4:$G$200)*BITACORA!$G$2 -> 15 | D21: =COUNT(BITACORA!$W$4:$W$200)*BITACORA!$G$2 -> 15 | E21: =IFERROR($C21/$D21,"") -> 1 | F21: =IF($D21=0,"",IF($E21>=0.9,"Sólido",IF($E21>=0.75,"Aceptable",IF($E21>=0.5,"Aquí se está fugando el resultado","Renglón crítico")))) -> Sólido
B22: Cardio 30 min | C22: =SUM(BITACORA!$H$4:$H$200)*BITACORA!$H$2 -> 6 | D22: =COUNT(BITACORA!$W$4:$W$200)*BITACORA!$H$2 -> 6 | E22: =IFERROR($C22/$D22,"") -> 1 | F22: =IF($D22=0,"",IF($E22>=0.9,"Sólido",IF($E22>=0.75,"Aceptable",IF($E22>=0.5,"Aquí se está fugando el resultado","Renglón crítico")))) -> Sólido
B23: Subtotal ENTRENAMIENTO | C23: =SUM(C21:C22) -> 21 | D23: =SUM(D21:D22) -> 21 | E23: =IFERROR($C23/$D23,"") -> 1
B25: NUTRICIÓN
B26: Proteína en meta | C26: =SUM(BITACORA!$R$4:$R$200)*BITACORA!$R$2 -> 12 | D26: =COUNT(BITACORA!$W$4:$W$200)*BITACORA!$R$2 -> 12 | E26: =IFERROR($C26/$D26,"") -> 1 | F26: =IF($D26=0,"",IF($E26>=0.9,"Sólido",IF($E26>=0.75,"Aceptable",IF($E26>=0.5,"Aquí se está fugando el resultado","Renglón crítico")))) -> Sólido
B27: Calorías en rango | C27: =SUM(BITACORA!$S$4:$S$200)*BITACORA!$S$2 -> 10 | D27: =COUNT(BITACORA!$W$4:$W$200)*BITACORA!$S$2 -> 10 | E27: =IFERROR($C27/$D27,"") -> 1 | F27: =IF($D27=0,"",IF($E27>=0.9,"Sólido",IF($E27>=0.75,"Aceptable",IF($E27>=0.5,"Aquí se está fugando el resultado","Renglón crítico")))) -> Sólido
B28: Agua 5 L | C28: =SUM(BITACORA!$T$4:$T$200)*BITACORA!$T$2 -> 8 | D28: =COUNT(BITACORA!$W$4:$W$200)*BITACORA!$T$2 -> 8 | E28: =IFERROR($C28/$D28,"") -> 1 | F28: =IF($D28=0,"",IF($E28>=0.9,"Sólido",IF($E28>=0.75,"Aceptable",IF($E28>=0.5,"Aquí se está fugando el resultado","Renglón crítico")))) -> Sólido
B29: Creatina + CoQ10 | C29: =SUM(BITACORA!$K$4:$K$200)*BITACORA!$K$2 -> 3 | D29: =COUNT(BITACORA!$W$4:$W$200)*BITACORA!$K$2 -> 3 | E29: =IFERROR($C29/$D29,"") -> 1 | F29: =IF($D29=0,"",IF($E29>=0.9,"Sólido",IF($E29>=0.75,"Aceptable",IF($E29>=0.5,"Aquí se está fugando el resultado","Renglón crítico")))) -> Sólido
B30: Subtotal NUTRICIÓN | C30: =SUM(C26:C29) -> 33 | D30: =SUM(D26:D29) -> 33 | E30: =IFERROR($C30/$D30,"") -> 1
B32: VIDA ESPIRITUAL
B33: Rosario | C33: =SUM(BITACORA!$I$4:$I$200)*BITACORA!$I$2 -> 6 | D33: =COUNT(BITACORA!$W$4:$W$200)*BITACORA!$I$2 -> 6 | E33: =IFERROR($C33/$D33,"") -> 1 | F33: =IF($D33=0,"",IF($E33>=0.9,"Sólido",IF($E33>=0.75,"Aceptable",IF($E33>=0.5,"Aquí se está fugando el resultado","Renglón crítico")))) -> Sólido
B34: Subtotal VIDA ESPIRITUAL | C34: =SUM(C33:C33) -> 6 | D34: =SUM(D33:D33) -> 6 | E34: =IFERROR($C34/$D34,"") -> 1
B36: CAPITAL HUMANO
B37: Estudio 2 h | C37: =SUM(BITACORA!$U$4:$U$200)*BITACORA!$U$2 -> 0 | D37: =COUNT(BITACORA!$W$4:$W$200)*BITACORA!$U$2 -> 13 | E37: =IFERROR($C37/$D37,"") -> 0 | F37: =IF($D37=0,"",IF($E37>=0.9,"Sólido",IF($E37>=0.75,"Aceptable",IF($E37>=0.5,"Aquí se está fugando el resultado","Renglón crítico")))) -> Renglón crítico
B38: Lectura 20 min | C38: =SUM(BITACORA!$J$4:$J$200)*BITACORA!$J$2 -> 0 | D38: =COUNT(BITACORA!$W$4:$W$200)*BITACORA!$J$2 -> 3 | E38: =IFERROR($C38/$D38,"") -> 0 | F38: =IF($D38=0,"",IF($E38>=0.9,"Sólido",IF($E38>=0.75,"Aceptable",IF($E38>=0.5,"Aquí se está fugando el resultado","Renglón crítico")))) -> Renglón crítico
B39: Subtotal CAPITAL HUMANO | C39: =SUM(C37:C38) -> 0 | D39: =SUM(D37:D38) -> 16 | E39: =IFERROR($C39/$D39,"") -> 0
B41: RECUPERACIÓN
B42: Sueño 6.5 h+ | C42: =SUM(BITACORA!$V$4:$V$200)*BITACORA!$V$2 -> 0 | D42: =COUNT(BITACORA!$W$4:$W$200)*BITACORA!$V$2 -> 6 | E42: =IFERROR($C42/$D42,"") -> 0 | F42: =IF($D42=0,"",IF($E42>=0.9,"Sólido",IF($E42>=0.75,"Aceptable",IF($E42>=0.5,"Aquí se está fugando el resultado","Renglón crítico")))) -> Renglón crítico
B43: Subtotal RECUPERACIÓN | C43: =SUM(C42:C42) -> 0 | D43: =SUM(D42:D42) -> 6 | E43: =IFERROR($C43/$D43,"") -> 0
B45: PUNTAJE TOTAL ACUMULADO | C45: =C18+C23+C30+C34+C39+C43 -> 78 | D45: =D18+D23+D30+D34+D39+D43 -> 100 | E45: =IFERROR($C45/$D45,"") -> 0.78 | F45: MARGEN DE CUMPLIMIENTO
B47: CÓMO LEER ESTE ESTADO
